<?xml version="1.0" encoding="utf-8"?>
<!-- This URDF was automatically created by SolidWorks to URDF Exporter! Originally created by Stephen Brawner (brawner@gmail.com) 
     Commit Version: 1.6.0-1-g15f4949  Build Version: 1.6.7594.29634
     For more information, please see http://wiki.ros.org/sw_urdf_exporter -->
<robot xmlns:xacro="http://www.ros.org/wiki/xacro" 
  name="assembly_hamster">

  <link
    name="base_link">
    <visual>
      <origin
        xyz="0 0 0"
        rpy="0 0 0" />
      <geometry>
        <mesh
          filename="package://assembly_hamster/meshes/base_link.STL" />
      </geometry>
      <material
        name="">
        <color
          rgba="0.75294 0.75294 0.75294 1" />
      </material>
    </visual>
    <collision>
      <origin
        xyz="0 0 0"
        rpy="0 0 0" />
      <geometry>
        <mesh
          filename="package://assembly_hamster/meshes/base_link.STL" />
      </geometry>
    </collision>
  </link>

  <link
    name="1_Link">
    <inertial>
      <origin
        xyz="0.01351 0.037179 -0.003383"
        rpy="0 0 0" />
      <mass
        value="2.6545" />
      <inertia
        ixx="0.0023682"
        ixy="8.0753E-05"
        ixz="1.7978E-05"
        iyy="0.0032175"
        iyz="4.8925E-05"
        izz="0.0021073" />
    </inertial>
    <visual>
      <origin
        xyz="0 0 0"
        rpy="0 0 0" />
      <geometry>
        <mesh
          filename="package://assembly_hamster/meshes/1_Link.STL" />
      </geometry>
      <material
        name="">
        <color
          rgba="0.75294 0.75294 0.75294 1" />
      </material>
    </visual>
    <collision>
      <origin
        xyz="0 0 0"
        rpy="0 0 0" />
      <geometry>
        <mesh
          filename="package://assembly_hamster/meshes/1_Link.STL" />
      </geometry>
    </collision>
  </link>

  <joint
    name="joint_1"
    type="revolute">
    <origin
      xyz="0 0 0.0202"
      rpy="1.5708 0 0" />
    <parent
      link="base_link" />
    <child
      link="1_Link" />
    <axis
      xyz="0 1 0" />
      <limit
      lower="-3"
      upper="3"
      effort="1000.0"
      velocity="0.1" />
  </joint>

  <link
    name="2_1_Link">
    <inertial>
      <origin
        xyz="-0.079036 -0.016436 -1.1424E-05"
        rpy="0 0 0" />
      <mass
        value="0.55117" />
      <inertia
        ixx="7.293E-05"
        ixy="4.1886E-08"
        ixz="1.1981E-07"
        iyy="0.00070853"
        iyz="4.1934E-08"
        izz="0.00068782" />
    </inertial>
    <visual>
      <origin
        xyz="0 0 0"
        rpy="0 0 0" />
      <geometry>
        <mesh
          filename="package://assembly_hamster/meshes/2_1_Link.STL" />
      </geometry>
      <material
        name="">
        <color
          rgba="0.75294 0.75294 0.75294 1" />
      </material>
    </visual>
    <collision>
      <origin
        xyz="0 0 0"
        rpy="0 0 0" />
      <geometry>
        <mesh
          filename="package://assembly_hamster/meshes/2_1_Link.STL" />
      </geometry>
    </collision>
  </link>

  <joint
    name="joint_2_1"
    type="revolute">
    <origin
      xyz="-0.0285 0.055 0"
      rpy="1.5708 0 -1.5708" />
    <parent
      link="1_Link" />
    <child
      link="2_1_Link" />
    <axis
      xyz="0 1 0" />
      <limit
      upper="1.5"
      lower="-0.8"
      effort="1000.0"
      velocity="0.1" />
  </joint>

  <link
    name="3_Link">
    <inertial>
      <origin
        xyz="-0.0704447246010788 0.343494150571024 -0.03888635607788"
        rpy="0 0 0" />
      <mass
        value="0.240854595463992" />
      <inertia
        ixx="5.70384323950151E-05"
        ixy="2.03886631821913E-05"
        ixz="-3.0839576044844E-08"
        iyy="0.000450948009144471"
        iyz="4.17435822214057E-09"
        izz="0.000492580105984167" />
    </inertial>
    <visual>
      <origin
        xyz="0 0 0"
        rpy="0 0 0" />
      <geometry>
        <mesh
          filename="package://assembly_hamster/meshes/3_Link.STL" />
      </geometry>
      <material
        name="">
        <color
          rgba="0.752941176470588 0.752941176470588 0.752941176470588 1" />
      </material>
    </visual>
    <collision>
      <origin
        xyz="0 0 0"
        rpy="0 0 0" />
      <geometry>
        <mesh
          filename="package://assembly_hamster/meshes/3_Link.STL" />
      </geometry>
    </collision>
  </link>

  <joint
    name="joint_3_base"
    type="fixed">
    <origin
      xyz="0.077076 0 0.024656"
      rpy="-1.5708 1.3472 0" />
    <parent
      link="2_1_Link" />
    <child
      link="3_Link" />
    <axis
      xyz="1 0 0" />
  </joint>

  <link
    name="3_1_Link">
    <inertial>
      <origin
        xyz="0.0225113352518309 0.0816101189194423 0.0111429600420675"
        rpy="0 0 0" />
      <mass
        value="0.706946980905885" />
      <inertia
        ixx="0.00157450700015675"
        ixy="3.60972844158452E-11"
        ixz="1.93929692550891E-06"
        iyy="0.000107129521994653"
        iyz="-7.73897691995558E-12"
        izz="0.00157126380530245" />
    </inertial>
    <visual>
      <origin
        xyz="0 0 0"
        rpy="0 0 0" />
      <geometry>
        <mesh
          filename="package://assembly_hamster/meshes/3_1_Link.STL" />
      </geometry>
      <material
        name="">
        <color
          rgba="0.752941176470588 0.752941176470588 0.752941176470588 1" />
      </material>
    </visual>
    <collision>
      <origin
        xyz="0 0 0"
        rpy="0 0 0" />
      <geometry>
        <mesh
          filename="package://assembly_hamster/meshes/3_1_Link.STL" />
      </geometry>
    </collision>
  </link>

  <joint
    name="joint_3_1"
    type="revolute">
    <origin
      xyz="-0.048498 0.3244 0"
      rpy="0 0 1.8008" />
    <parent
      link="3_Link" />
    <child
      link="3_1_Link" />
    <axis
      xyz="0 0 1" />
      <limit
      lower="-3"
      upper="1.3"
      effort="1000.0"
      velocity="0.1" />
  </joint>

  <link
    name="last_Link">
    <inertial>
      <origin
        xyz="0.00458290320651195 0.00403833478304899 -0.0619326448877698"
        rpy="0 0 0" />
      <mass
        value="1.25124090194283" />
      <inertia
        ixx="0.000910187410735932"
        ixy="-8.26464406621072E-05"
        ixz="-0.000139433164917929"
        iyy="0.00114548708038895"
        iyz="-8.56917911613583E-05"
        izz="0.000580086863956969" />
    </inertial>
    <visual>
      <origin
        xyz="0 0 0"
        rpy="0 0 0" />
      <geometry>
        <mesh
          filename="package://assembly_hamster/meshes/last_Link.STL" />
      </geometry>
      <material
        name="">
        <color
          rgba="0.752941176470588 0.752941176470588 0.752941176470588 1" />
      </material>
    </visual>
    <collision>
      <origin
        xyz="0 0 0"
        rpy="0 0 0" />
      <geometry>
        <mesh
          filename="package://assembly_hamster/meshes/last_Link.STL" />
      </geometry>
    </collision>
  </link>

<link
name="last_Link_2">
</link>

  <joint
    name="joint_last_2"
    type="revolute">
    <origin
      xyz="0 0.25 -0.0005"
      rpy="3.14 -1.57 -1.5708"/>
    <parent
      link="3_1_Link" />
    <child
      link="last_Link_2" />
    <axis
      xyz="1 0 0" />
       <mimic joint="joint_2_1"  multiplier="-1" offset="0" /> 
  <limit
      lower="-3"
      upper="3"
      effort="1000.0"
      velocity="0.1" />
  </joint>

  <joint
    name="joint_last"
    type="revolute">
    <origin
       xyz="0 0 0"
      rpy="0 0 0"/>
    <parent
      link="last_Link_2" />
    <child
      link="last_Link" />
    <axis
      xyz="1 0 0" />
       <mimic joint="joint_3_1"  multiplier="-1" offset="0" /> 
  <limit
      lower="-3"
      upper="3"
      effort="1000.0"
      velocity="0.1" />
  </joint>


 
<link
name="end_link">
</link>

<joint
    name="joint_gripper"
    type="revolute">
    <origin
      xyz="0 0.032 -0.045"
      rpy="1.5708 0 3.1416" />
    <parent
      link="last_Link" />
    <child
      link="end_link" />
    <axis
      xyz="0 0 1" />
      <limit
      lower="-3.14"
      upper="3.14"
      effort="1000.0" 
      velocity="0.1" />
  </joint>

  <link
    name="gripper">
    <inertial>
      <origin
        xyz="5.86233622760363E-06 -0.000606087650654452 0.0417223441506261"
        rpy="0 0 0" />
      <mass
        value="0.442243456619388" />
      <inertia
        ixx="8.43721038666399E-05"
        ixy="2.09810431459494E-07"
        ixz="-2.31972138398739E-07"
        iyy="8.65761187754296E-05"
        iyz="2.91645480078844E-06"
        izz="7.21955526660134E-05" />
    </inertial>
    <visual>
      <origin
        xyz="0 0 0"
        rpy="0 0 0" />
      <geometry>
        <mesh
          filename="package://assembly_hamster/meshes/end_Link.STL" />
      </geometry>
      <material
        name="">
        <color
          rgba="0.752941176470588 0.752941176470588 0.752941176470588 1" />
      </material>
    </visual>
    <collision>
      <origin
        xyz="0 0 0"
        rpy="0 0 0" />
      <geometry>
        <mesh
          filename="package://assembly_hamster/meshes/end_Link.STL" />
      </geometry>
    </collision>
  </link>

  <joint
    name="joint_end_effector"
    type="fixed">
    <origin
      xyz="0 0 0"
      rpy="0 0 0" />
    <parent
      link="end_link" />
    <child
      link="gripper" />
  </joint>


      <gazebo>
        <plugin name="gazebo_ros_control" filename="libgazebo_ros_control.so">
        <robotNamespace>/assembly_hamster</robotNamespace>
        </plugin>
    </gazebo>
    
</robot>